<?xml version="1.0" encoding="UTF-8"?>
<!-- Generated by org.testng.reporters.JUnitReportReporter -->
<testsuite hostname="DESKTOP-A8FMS7E" failures="1" tests="6" name="Overall.SeleniumFramework1.Error_Validation" time="20.377" errors="0" timestamp="2024-10-31T17:42:10 IST" skipped="3">
  <testcase classname="Overall.SeleniumFramework1.Error_Validation" name="submitOrder" time="2.850"/>
  <system-out/>
  <testcase classname="Overall.SeleniumFramework1.Error_Validation" name="OrderHistorytest" time="3.020">
    <failure message="expected [true] but found [false]" type="java.lang.AssertionError">
      <![CDATA[java.lang.AssertionError: expected [true] but found [false]
at org.testng.Assert.fail(Assert.java:99)
at org.testng.Assert.failNotEquals(Assert.java:1037)
at org.testng.Assert.assertTrue(Assert.java:45)
at org.testng.Assert.assertTrue(Assert.java:55)
at Overall.SeleniumFramework1.Error_Validation.OrderHistorytest(Error_Validation.java:66)
at java.base/jdk.internal.reflect.DirectMethodHandleAccessor.invoke(DirectMethodHandleAccessor.java:103)
at java.base/java.lang.reflect.Method.invoke(Method.java:580)
at org.testng.internal.MethodInvocationHelper.invokeMethod(MethodInvocationHelper.java:133)
at org.testng.internal.TestInvoker.invokeMethod(TestInvoker.java:598)
at org.testng.internal.TestInvoker.retryFailed(TestInvoker.java:213)
at org.testng.internal.MethodRunner.runInSequence(MethodRunner.java:58)
at org.testng.internal.TestInvoker$MethodInvocationAgent.invoke(TestInvoker.java:824)
at org.testng.internal.TestInvoker.invokeTestMethods(TestInvoker.java:146)
at org.testng.internal.TestMethodWorker.invokeTestMethods(TestMethodWorker.java:146)
at org.testng.internal.TestMethodWorker.run(TestMethodWorker.java:128)
at java.base/java.util.ArrayList.forEach(ArrayList.java:1596)
at org.testng.TestRunner.privateRun(TestRunner.java:794)
at org.testng.TestRunner.run(TestRunner.java:596)
at org.testng.SuiteRunner.runTest(SuiteRunner.java:377)
at org.testng.SuiteRunner.runSequentially(SuiteRunner.java:371)
at org.testng.SuiteRunner.privateRun(SuiteRunner.java:332)
at org.testng.SuiteRunner.run(SuiteRunner.java:276)
at org.testng.SuiteRunnerWorker.runSuite(SuiteRunnerWorker.java:53)
at org.testng.SuiteRunnerWorker.run(SuiteRunnerWorker.java:96)
at org.testng.TestNG.runSuitesSequentially(TestNG.java:1212)
at org.testng.TestNG.runSuitesLocally(TestNG.java:1134)
at org.testng.TestNG.runSuites(TestNG.java:1063)
at org.testng.TestNG.run(TestNG.java:1031)
at org.testng.remote.AbstractRemoteTestNG.run(AbstractRemoteTestNG.java:115)
at org.testng.remote.RemoteTestNG.initAndRun(RemoteTestNG.java:293)
at org.testng.remote.RemoteTestNG.main(RemoteTestNG.java:91)
]]>
    </failure>
  </testcase> <!-- OrderHistorytest -->
  <system-out/>
  <testcase classname="Overall.SeleniumFramework1.Error_Validation" name="OrderHistorytest" time="2.426">
    <skipped/>
  </testcase> <!-- OrderHistorytest -->
  <system-out/>
  <testcase classname="Overall.SeleniumFramework1.Error_Validation" name="OrderHistorytest" time="3.877">
    <skipped/>
  </testcase> <!-- OrderHistorytest -->
  <system-out/>
  <testcase classname="Overall.SeleniumFramework1.Error_Validation" name="ProductErrorValidation" time="5.862"/>
  <system-out/>
  <testcase classname="Overall.SeleniumFramework1.Error_Validation" name="OrderHistorytest" time="2.342">
    <skipped/>
  </testcase> <!-- OrderHistorytest -->
  <system-out/>
</testsuite> <!-- Overall.SeleniumFramework1.Error_Validation -->
